Workbook

Sheet Formula
A1: Composition | B1: Element 1 (line)* | C1: index 1 | D1: Element 2 (line) | E1: index 2 | F1: Element 3 (line)** | G1: index 3 | H1: Element 4 (line) | I1: index 4 | J1: Element 5(line) | K1: index 5 | L1: Dopants | M1: Dopant 1(line) | N1: Best Concentration | O1: Crystal System | P1: Space Group | T1: DOI
A2: Na4Ca(PO3)6 | B2: 12 | C2: 4 | D2: 21 | E2: 1 | F2: 16 | G2: 6 | H2: 9 | I2: 18 | J2: 87 | K2: 0 | L2: Eu3+ | M2: 64 | N2: 0.04 | O2: 2 | P2: 15 | T2: https://doi.org/10.1016/j.chphi.2024.10071
A3: PbZrO3 | B3: 83 | C3: 1 | D3: 41 | E3: 1 | F3: 9 | G3: 3 | H3: 87 | I3: 0 | J3: 87 | K3: 0 | L3: Eu3+ | M3: 64 | N3: 0.07 | O3: 3 | P3: 55 | T3: https://doi.org/10.1016/j.saa.2023.123005
A4: Ca3Al2O6 | B4: 21 | C4: 3 | D4: 14 | E4: 2 | F4: 9 | G4: 6 | H4: 87 | I4: 0 | J4: 87 | K4: 0 | L4: Eu3+ | M4: 64 | N4: 0.04 | O4: 7 | P4: 221 | T4: https://doi.org/10.1016/S1002-0721(16)60153-9
A5: CaLa4Si3O13 | B5: 21 | C5: 1 | D5: 58 | E5: 4 | F5: 15 | G5: 3 | H5: 9 | I5: 13 | J5: 87 | K5: 0 | L5: Eu3+ | M5: 64 | N5: 0.04 | O5: 6 | P5: 176 | T5: https://doi.org/10.1016/j.ceramint.2022.06.036
A6: YPO4 | B6: 40 | C6: 1 | D6: 16 | E6: 1 | F6: 9 | G6: 4 | H6: 87 | I6: 0 | J6: 87 | K6: 0 | L6: Eu3+ | M6: 64 | N6: 0.05 | O6: 4 | P6: 141 | T6: https://doi.org/10.1016/j.matpr.2022.04.055
A7: SnO2 | B7: 51 | C7: 1 | D7: 9 | E7: 2 | F7: 87 | G7: 0 | H7: 87 | I7: 0 | J7: 87 | K7: 0 | L7: Eu3+ | M7: 64 | N7: 0.03 | O7: 4 | P7: 136 | T7: https://doi.org/10.1016/j.jallcom.2020.153640
A8: HfO2 | B8: 73 | C8: 1 | D8: 9 | E8: 2 | F8: 87 | G8: 0 | H8: 87 | I8: 0 | J8: 87 | K8: 0 | L8: Eu3+ | M8: 64 | N8: 0.05 | O8: 2 | P8: 14 | T8: https://doi.org/10.1016/j.ceramint.2018.01.250
A9: Ca3Si2O7 | B9: 21 | C9: 3 | D9: 15 | E9: 2 | F9: 9 | G9: 7 | H9: 87 | I9: 0 | J9: 87 | K9: 0 | L9: Eu3+ | M9: 64 | N9: 0.09 | O9: 2 | P9: 14 | T9: https://doi.org/10.1016/j.jallcom.2021.162265
A10: Sr3Ga2Ge4O14 | B10: 39 | C10: 3 | D10: 32 | E10: 2 | F10: 33 | G10: 4 | H10: 9 | I10: 14 | J10: 87 | K10: 0 | L10: Eu3+ | M10: 64 | N10: 0.05 | O10: 5 | P10: 150 | T10: https://doi.org/10.1016/j.optmat.2023.113528
A11: YBO3 | B11: 40 | C11: 1 | D11: 6 | E11: 1 | F11: 9 | G11: 1 | H11: 87 | I11: 0 | J11: 87 | K11: 0 | L11: Eu3+ | M11: 64 | N11: 0.02 | O11: 2 | P11: 15 | T11: http://dx.doi.org/10.1016/j.spmi.2013.12.026
A12: Ba2Si4O10 | B12: 57 | C12: 2 | D12: 15 | E12: 4 | F12: 9 | G12: 10 | H12: 87 | I12: 0 | J12: 87 | K12: 0 | L12: Eu3+ | M12: 64 | N12: 0.02 | O12: 3 | P12: 62 | T12: http://dx.doi.org/10.1016/j.jlumin.2016.07.013
A13: Ca19Mg2(PO4)14 | B13: 21 | C13: 19 | D13: 13 | E13: 2 | F13: 16 | G13: 14 | H13: 9 | I13: 56 | J13: 87 | K13: 0 | L13: Eu3+ | M13: 64 | N13: 0.1 | O13: 5 | P13: 161 | T13: https://doi.org/10.1016/j.jallcom.2020.156070
... A75: Na3Bi5(PO4)6 | B75: 12 | C75: 3 | D75: 84 | E75: 5 | F75: 16 | G75: 6 | H75: 9 | I75: 24 | J75: 87 | K75: 0 | L75: Eu3+ | M75: 64 | N75: 0.05 | O75: 7 | P75: 220 | T75: https://doi.org/10.1016/j.ceramint.2022.02.046
A76: SrAl2O4 | B76: 39 | C76: 1 | D76: 14 | E76: 2 | F76: 9 | G76: 4 | H76: 87 | I76: 0 | J76: 87 | K76: 0 | L76: Eu3+ | M76: 64 | N76: 0.01 | O76: 2 | P76: 4
A77: SrMg2La2W2O12 | B77: 39 | C77: 1 | D77: 13 | E77: 2 | F77: 58 | G77: 2 | H77: 75 | I77: 2 | J77: 9 | K77: 12 | L77: Eu3+ | M77: 64 | N77: 0.08 | O77: 3 | P77: 16 | T77: https://doi.org/10.1016/j.jpcs.2021.110569
A78: GdSr2AlO5 | B78: 65 | C78: 1 | D78: 39 | E78: 2 | F78: 14 | G78: 1 | H78: 9 | I78: 5 | J78: 87 | K78: 0 | L78: Eu3+ | M78: 64 | N78: 0.03 | O78: 4 | P78: 140 | T78: https://doi.org/10.1016/j.jallcom.2023.171410
A79: Ba2La8(GeO4)6O2 | B79: 57 | C79: 2 | D79: 58 | E79: 8 | F79: 33 | G79: 6 | H79: 9 | I79: 26 | J79: 87 | K79: 0 | L79: Eu3+ | M79: 64 | N79: 0.08 | O79: 6 | P79: 176 | T79: https://doi.org/10.1016/j.jre.2020.10.019
A80: LaCaAl3O7 | B80: 58 | C80: 1 | D80: 21 | E80: 1 | F80: 14 | G80: 3 | H80: 9 | I80: 7 | J80: 87 | K80: 0 | L80: Eu3+ | M80: 64 | N80: 0.03 | O80: 2 | P80: 11 | T80: https://doi.org/10.1016/j.jtice.2025.106145
A81: Bi2Mo3O12 | B81: 84 | C81: 2 | D81: 43 | E81: 3 | F81: 9 | G81: 12 | H81: 87 | I81: 0 | J81: 87 | K81: 0 | L81: Eu3+ | M81: 64 | N81: 0.04 | O81: 2 | P81: 14 | T81: https://doi.org/10.1016/j.jallcom.2024.175566
A82: Ca9MgLi(PO4)7 | B82: 21 | C82: 9 | D82: 13 | E82: 1 | F82: 4 | G82: 1 | H82: 16 | I82: 7 | J82: 9 | K82: 28 | L82: Eu3+ | M82: 64 | N82: 0.08 | O82: 5 | P82: 161 | T82: https://doi.org/10.1016/j.jlumin.2022.119397
A83: ZnTiO3 | B83: 31 | C83: 1 | D83: 23 | E83: 1 | F83: 9 | G83: 3 | H83: 87 | I83: 0 | J83: 87 | K83: 0 | L83: Eu3+ | M83: 64 | N83: 0.02 | O83: 5 | P83: 161 | T83: https://doi.org/10.1016/S1002-0721(14)60408-7
A84: NaCa4(BO3)3 | B84: 12 | C84: 1 | D84: 21 | E84: 4 | F84: 6 | G84: 3 | H84: 9 | I84: 9 | J84: 87 | K84: 0 | L84: Eu3+ | M84: 64 | N84: 0.08 | O84: 3 | P84: 40 | T84: https://doi.org/10.1016/j.jallcom.2010.04.242
A85: LiCaBO3 | B85: 4 | C85: 1 | D85: 21 | E85: 1 | F85: 6 | G85: 1 | H85: 9 | I85: 3 | J85: 87 | K85: 0 | L85: Eu3+ | M85: 64 | N85: 0.03 | O85: 3 | P85: 61 | T85: https://doi.org/10.1016/S1002-0721(08)60257-4
A86: LaAlO3 | B86: 58 | C86: 1 | D86: 14 | E86: 1 | F86: 9 | G86: 3 | H86: 87 | I86: 0 | J86: 87 | K86: 0 | L86: Eu3+ | M86: 64 | N86: 0.02 | O86: 5 | P86: 160 | T86: https://doi.org/10.1016/j.jallcom.2024.177504
A87: CaZnV2O7 | B87: 21 | C87: 1 | D87: 31 | E87: 1 | F87: 25 | G87: 2 | H87: 9 | I87: 7 | J87: 87 | K87: 0 | L87: Eu3+ | M87: 64 | N87: 0.02 | O87: 2 | P87: 14 | T87: https://doi.org/10.1016/j.jlumin.2019.116530
A88: Ca3La6Si6O24 | B88: 21 | C88: 3 | D88: 58 | E88: 6 | F88: 15 | G88: 6 | H88: 9 | I88: 24 | J88: 87 | K88: 0 | L88: Eu3+ | M88: 64 | N88: 0.08 | O88: 6 | P88: 176 | T88: https://doi.org/10.1016/j.materresbull.2019.110651
... A121: PbMoO4 | B121: 83 | C121: 1 | D121: 43 | E121: 1 | F121: 9 | G121: 4 | H121: 87 | I121: 0 | J121: 87 | K121: 0 | L121: Eu3+ | M121: 64 | N121: 0.05 | O121: 4 | P121: 88 | T121: https://doi.org/10.1016/j.jphotochem.2015.08.009

Sheet Properties
A1: Symbol | B1: Electron configuration | C1: Atomic weight | D1: Atomic number | E1: Period | F1: Group | G1: quantum number l | H1: Metal(1)/ metalloid(2)/ nonmetal(3) | I1: Mendeleev number | J1: Families | K1: valence s | L1: valence p | M1: valence d | N1: valence f | O1: unfilled s | P1: unfilled p | Q1: unfilled d | R1: unfilled f | S1: no. of valence electrons | T1: outer shell electrons | U1: Gilman no. of valence electrons | V1: Pauling valence, v | W1: Metallic valence | X1: Zeff | Y1: 1st Bohr radius (a0) | Z1: Ionization energy (eV) | AA1: Electron affinity (ev) | AB1: Pearson absolute (eV) | AC1: Ghosh Gupta (eV) | AD1: Pauling EN | AE1: Martynov Batsanov EN | AF1: Mulliken EN | AG1: Allred EN | AH1: Allred Rockow EN | AI1: Nagle EN | AJ1: Putz Russo Sicillia EN | AK1: Gordy EN | AL1: Ghosh EN | AM1: Atomic radius calculated | AN1: Covalent radius | AO1: Ionic radius | AP1: Effective ionic radius | AQ1: Miracle radius | AR1: van der Waals radius | AS1: Zunger radii sum | AT1: Crystal radius | AU1: Covalent CSD radius | AV1: Slater radius | AW1: Orbital radius | AX1: Pauling, R(CN12) | AY1: Pauling, R(1) | AZ1: polarizability, A^3 | BA1: Melting point, K | BB1: Boiling point, K | BC1: Density, g/mL | BD1: Specific heat, J/g K | BE1: Heat of fusion, kJ/mol | BF1: Heat of vaporization, kJ/mol | BG1: Heat of atomization, kJ/mol | BH1: Thermal conductivity, W/m K | BI1: Thermal expansion, K^-1 | BJ1: Cohesive energy | BK1: Bulk modulus, GPa | BL1: Sheer modulus, GPa | BM1: Young modulus, GPa | BN1: Hardness Vickers, GPa | BO1: Hardness Brinell, GPa | BP1: Resistivity (mΩ) | BQ1: Electrical Conductivity (S/m) | BR1: Neutron Cross Section | BS1: Neutron Mass Absorption | BT1: no. of Known Isotopes | BU1: no. of Stable Isotopes | BV1: fraction of stable isotopes | BW1: fraction abundance of stable isotopes | BX1: Abundance in Earth's crust | BY1: Abundance in solar system (log) | BZ1: HHI production | CA1: HHI reserve | CB1: cost, pure ($/100g)
A2: H | B2: 1s1 | C2: 1.00794 | D2: 1 | E2: 1 | F2: 1 | G2: 0 | H2: 3 | I2: 92 | J2: 7 | K2: 1 | L2: 0 | M2: 0 | N2: 0 | O2: 1 | P2: 6 | Q2: 10 | R2: 14 | S2: 1 | T2: 1 | U2: 1 | V2: N/A | W2: 0 | X2: 1 | Y2: 0.529 | Z2: 13.5984 | AA2: 0.75661829 | AB2: 7.18 | AC2: 7.1862 | AD2: 2.2 | AE2: 2.1 | AF2: 7.18 | AG2: 2.2 | AH2: 2.3 | AI2: 2.27 | AJ2: N/A | AK2: 2.13 | AL2: 8.22 | AM2: 0.53 | AN2: 0.37 | AO2: 0.11 | AP2: 0.1 | AQ2: 0.51 | AR2: 1.2 | AS2: 1.25 | AT2: 0.1 | AU2: 0.31 | AV2: 0.25 | AW2: 0.529 | AX2: N/A | AY2: N/A | AZ2: 0.7 | BA2: 14.05 | BB2: 20.25 | BC2: 0.0899 | BD2: 14.304 | BE2: 0.5868 | BF2: 0.44936 | BG2: 218 | BH2: 0.1815 | BI2: N/A | BJ2: N/A | BK2: 0.2 | BL2: N/A | BM2: N/A | BN2: N/A | BO2: N/A | BP2: N/A | BQ2: N/A | BR2: 0.332 | BS2: 0.011 | BT2: 7 | BU2: 2 | BV2: 0.28571429 | BW2: 1 | BX2: 0.0014292853 | BY2: 0.90985095 | BZ2: N/A | CA2: N/A | CB2: 12
A3: He | B3: 1s2 | C3: 4.002602 | D3: 2 | E3: 1 | F3: 18 | G3: 0 | H3: 3 | I3: 98 | J3: 9 | K3: 2 | L3: 0 | M3: 0 | N3: 0 | O3: 0 | P3: 6 | Q3: 10 | R3: 14 | S3: 2 | T3: 2 | U3: 2 | V3: N/A | W3: 0 | X3: 1.344 | Y3: 0.394 | Z3: 24.5874 | AA3: -0.51828415 | AB3: N/A | AC3: 12.0568 | AD3: N/A | AE3: N/A | AF3: N/A | AG3: N/A | AH3: 4.16 | AI3: 3.92 | AJ3: N/A | AK3: N/A | AL3: 40.4 | AM3: 0.31 | AN3: 0.32 | AO3: 0.58 | AP3: 0.56 | AQ3: 1.19 | AR3: 1.4 | AS3: 1.69 | AT3: 0.57 | AU3: 0.28 | AV3: 0.31 | AW3: 0.291 | AX3: N/A | AY3: N/A | AZ3: 0.198 | BA3: 0.95 | BB3: 4.25 | BC3: 0.1785 | BD3: 5.193 | BE3: 0.02 | BF3: 0.0845 | BG3: 0 | BH3: 0.152 | BI3: N/A | BJ3: N/A | BK3: N/A | BL3: N/A | BM3: N/A | BN3: N/A | BO3: N/A | BP3: N/A | BQ3: N/A | BR3: 0.007 | BS3: 1e-05 | BT3: 9 | BU3: 2 | BV3: 0.22222222 | BW3: 1 | BX3: 8.1673446e-09 | BY3: 0.088702315 | BZ3: N/A | CA3: N/A | CB3: 5.2
A4: Li | B4: [He]2s1 | C4: 6.941 | D4: 3 | E4: 2 | F4: 1 | G4: 0 | H4: 1 | I4: 1 | J4: 1 | K4: 1 | L4: 0 | M4: 0 | N4: 0 | O4: 1 | P4: 6 | Q4: 10 | R4: 14 | S4: 1 | T4: 1 | U4: 1 | V4: 1 | W4: 1 | X4: 1.259 | Y4: 1.681 | Z4: 5.3917 | AA4: 0.62211923 | AB4: 3.01 | AC4: 2.4435 | AD4: 0.98 | AE4: 0.9 | AF4: 3.01 | AG4: 0.98 | AH4: 0.912 | AI4: 0.94 | AJ4: 3.02 | AK4: 0.95 | AL4: 1.13 | AM4: 1.67 | AN4: 1.34 | AO4: 0.9 | AP4: 0.76 | AQ4: 1.52 | AR4: 1.82 | AS4: 1.61 | AT4: 0.9 | AU4: 1.28 | AV4: 1.45 | AW4: 1.586 | AX4: 1.549 | AY4: 1.225 | AZ4: 24.3 | BA4: 453.65 | BB4: 1615.15 | BC4: 0.535 | BD4: 3.6 | BE4: 3 | BF4: 145.92 | BG4: 161 | BH4: 84.7 | BI4: 4.6e-05 | BJ4: 1.63 | BK4: 11.6 | BL4: 4.2 | BM4: 4.9 | BN4: N/A | BO4: 0.005 | BP4: 9.4e-08 | BQ4: 11000000 | BR4: 71 | BS4: N/A | BT4: 10 | BU4: 2 | BV4: 0.2 | BW4: 1 | BX4: 2.0418362e-05 | BY4: 1.8620964e-09 | BZ4: 2850 | CA4: 4180 | CB4: 27
A5: Be | B5: [He]2s2 | C5: 9.01218 | D5: 4 | E5: 2 | F5: 2 | G5: 0 | H5: 1 | I5: 67 | J5: 2 | K5: 2 | L5: 0 | M5: 0 | N5: 0 | O5: 0 | P5: 6 | Q5: 10 | R5: 14 | S5: 2 | T5: 2 | U5: 2 | V5: 2 | W5: 2 | X5: 1.656 | Y5: 1.278 | Z5: 9.3227 | AA5: -0.51850389 | AB5: 4.9 | AC5: 3.706 | AD5: 1.57 | AE5: 1.45 | AF5: 4.9 | AG5: 1.57 | AH5: 1.576 | AI5: 1.55 | AJ5: 3.4 | AK5: 1.45 | AL5: 3.81 | AM5: 1.12 | AN5: 0.9 | AO5: 0.59 | AP5: 0.45 | AQ5: 1.12 | AR5: 1.53 | AS5: 1.08 | AT5: 0.41 | AU5: 0.96 | AV5: 1.05 | AW5: 1.04 | AX5: 1.123 | AY5: 0.889 | AZ5: 5.6 | BA5: 1551.15 | BB5: 3243.15 | BC5: 1.85 | BD5: 1.82 | BE5: 7.95 | BF5: 292.4 | BG5: 324 | BH5: 200 | BI5: 1.13e-05 | BJ5: 3.32 | BK5: 110 | BL5: 132 | BM5: 287 | BN5: 1.67 | BO5: 0.6 | BP5: 4e-08 | BQ5: 25000000 | BR5: 0.0092 | BS5: 3e-05 | BT5: 12 | BU5: 1 | BV5: 0.083333333 | BW5: 1 | BX5: 2.8585706e-06 | BY5: 2.3806136e-11 | BZ5: 8074 | CA5: 4000 | CB5: 530
A6: B | B6: [He]2s22p1 | C6: 10.811 | D6: 5 | E6: 2 | F6: 13 | G6: 1 | H6: 2 | I6: 72 | J6: 6 | K6: 2 | L6: 1 | M6: 0 | N6: 0 | O6: 0 | P6: 5 | Q6: 10 | R6: 14 | S6: 3 | T6: 3 | U6: 3 | V6: 3 | W6: 3 | X6: 1.561 | Y6: 1.355 | Z6: 8.298 | AA6: 0.27970787 | AB6: 4.29 | AC6: 4.9686 | AD6: 2.04 | AE6: 1.9 | AF6: 4.29 | AG6: 2.04 | AH6: 2.051 | AI6: 2.02 | AJ6: 5.66 | AK6: 1.9 | AL6: 9.04 | AM6: 0.87 | AN6: 0.82 | AO6: 0.41 | AP6: 0.27 | AQ6: 0.78 | AR6: 1.8 | AS6: 0.8 | AT6: 0.25 | AU6: 0.84 | AV6: 0.85 | AW6: 0.776 | AX6: 0.98 | AY6: 0.8 | AZ6: 3 | BA6: 2352.15 | BB6: 4275 | BC6: 2.34 | BD6: 1.02 | BE6: 50.2 | BF6: 489.7 | BG6: 573 | BH6: 27 | BI6: 6e-06 | BJ6: 5.81 | BK6: 178 | BL6: N/A | BM6: N/A | BN6: 49 | BO6: N/A | BP6: 10000 | BQ6: 0.0001 | BR6: 760 | BS6: 2.4 | BT6: 14 | BU6: 2 | BV6: 0.14285714 | BW6: 1 | BX6: 1.0209181e-05 | BY6: 6.9135628e-10 | BZ6: 2929 | CA6: 1980 | CB6: 250
A7: C | B7: [He]2s22p2 | C7: 12.011 | D7: 6 | E7: 2 | F7: 14 | G7: 1 | H7: 3 | I7: 77 | J7: 7 | K7: 2 | L7: 2 | M7: 0 | N7: 0 | O7: 0 | P7: 4 | Q7: 10 | R7: 14 | S7: 4 | T7: 4 | U7: 4 | V7: 4 | W7: 4 | X7: 1.8193 | Y7: 1.163 | Z7: 11.2603 | AA7: 1.2649692 | AB7: 6.27 | AC7: 6.2338 | AD7: 2.55 | AE7: 2.37 | AF7: 6.27 | AG7: 2.55 | AH7: 2.544 | AI7: 2.55 | AJ7: 8.58 | AK7: 2.55 | AL7: 17.6 | AM7: 0.67 | AN7: 0.77 | AO7: 0.4 | AP7: 0.16 | AQ7: 0.77 | AR7: 1.7 | AS7: 0.64 | AT7: 0.29 | AU7: 0.76 | AV7: 0.7 | AW7: 0.62 | AX7: 0.914 | AY7: 0.771 | AZ7: 1.8 | BA7: 3640.15 | BB7: 5100.15 | BC7: 2.25 | BD7: 0.71 | BE7: 105 | BF7: 355.8 | BG7: 717 | BH7: 129 | BI7: 7.1e-06 | BJ7: 7.37 | BK7: 443 | BL7: N/A | BM7: N/A | BN7: N/A | BO7: N/A | BP7: 1e-05 | BQ7: 100000 | BR7: 0.0035 | BS7: 1.5e-05 | BT7: 15 | BU7: 2 | BV7: 0.13333333 | BW7: 1 | BX7: 0.00020418362 | BY7: 0.00032937257 | BZ7: 500 | CA7: 500 | CB7: 2.4
A8: N | B8: [He]2s22p3 | C8: 14.00674 | D8: 7 | E8: 2 | F8: 15 | G8: 1 | H8: 3 | I8: 82 | J8: 7 | K8: 2 | L8: 3 | M8: 0 | N8: 0 | O8: 0 | P8: 3 | Q8: 10 | R8: 14 | S8: 5 | T8: 5 | U8: 5 | V8: 3 | W8: 3 | X8: 2.068 | Y8: 1.023 | Z8: 14.5341 | AA8: -0.00072566833 | AB8: 7.3 | AC8: 7.4964 | AD8: 3.04 | AE8: 2.85 | AF8: 7.3 | AG8: 3.04 | AH8: 3.066 | AI8: 3.12 | AJ8: 9.77 | AK8: 2.98 | AL8: 30.5 | AM8: 0.56 | AN8: 0.75 | AO8: 1.32 | AP8: 1.46 | AQ8: 0.72 | AR8: 1.55 | AS8: 0.54 | AT8: 0.3 | AU8: 0.71 | AV8: 0.65 | AW8: 0.521 | AX8: 0.88 | AY8: 0.7 | AZ8: 1.1 | BA8: 63.25 | BB8: 77.35 | BC8: 0.00125 | BD8: 1.04 | BE8: 0.3604 | BF8: 2.7928 | BG8: 473 | BH8: 0.02598 | BI8: N/A | BJ8: 4.92 | BK8: 1.2 | BL8: N/A | BM8: N/A | BN8: N/A | BO8: N/A | BP8: N/A | BQ8: N/A | BR8: 1.91 | BS8: 0.0048 | BT8: 16 | BU8: 2 | BV8: 0.125 | BW8: 1 | BX8: 1.9397443e-05 | BY8: 0.00010207288 | BZ8: 1329 | CA8: 500 | CB8: 0.4
A9: O | B9: [He]2s22p4 | C9: 15.9994 | D9: 8 | E9: 2 | F9: 16 | G9: 1 | H9: 3 | I9: 87 | J9: 7 | K9: 2 | L9: 4 | M9: 0 | N9: 0 | O9: 0 | P9: 2 | Q9: 10 | R9: 14 | S9: 6 | T9: 6 | U9: 6 | V9: 2 | W9: 0 | X9: 2.001 | Y9: 1.058 | Z9: 13.6181 | AA9: 1.461303 | AB9: 7.54 | AC9: 8.7861 | AD9: 3.44 | AE9: 3.32 | AF9: 7.54 | AG9: 3.44 | AH9: 3.61 | AI9: 3.62 | AJ9: 12.41 | AK9: 3.45 | AL9: 48.4 | AM9: 0.48 | AN9: 0.73 | AO9: 1.26 | AP9: 1.4 | AQ9: 0.64 | AR9: 1.52 | AS9: 0.47 | AT9: 1.21 | AU9: 0.66 | AV9: 0.6 | AW9: 0.45 | AX9: N/A | AY9: 0.66 | AZ9: 0.793 | BA9: 54.75 | BB9: 90.15 | BC9: 0.00143 | BD9: 0.92 | BE9: 0.22259 | BF9: 3.4099 | BG9: 249 | BH9: 0.02674 | BI9: N/A | BJ9: 2.62 | BK9: 2.2469487 | BL9: N/A | BM9: N/A | BN9: N/A | BO9: N/A | BP9: N/A | BQ9: N/A | BR9: 0.00028 | BS9: 1e-06 | BT9: 17 | BU9: 3 | BV9: 0.17647059 | BW9: 1 | BX9: 0.47064323 | BY9: 0.00077614525 | BZ9: 500 | CA9: 500 | CB9: 0.3
A10: F | B10: [He]2s22p5 | C10: 18.998403 | D10: 9 | E10: 2 | F10: 17 | G10: 1 | H10: 3 | I10: 93 | J10: 8 | K10: 2 | L10: 5 | M10: 0 | N10: 0 | O10: 0 | P10: 1 | Q10: 10 | R10: 14 | S10: 7 | T10: 7 | U10: 7 | V10: 1 | W10: 0 | X10: 2.263 | Y10: 0.835 | Z10: 17.4228 | AA10: 3.3995707 | AB10: 10.41 | AC10: 10.0378 | AD10: 3.98 | AE10: 3.78 | AF10: 10.41 | AG10: 3.98 | AH10: 4.193 | AI10: 4.23 | AJ10: 15.6 | AK10: 3.95 | AL10: 72.3 | AM10: 0.42 | AN10: 0.71 | AO10: 1.19 | AP10: 1.33 | AQ10: 0.66 | AR10: 1.47 | AS10: 0.41 | AT10: 1.19 | AU10: 0.57 | AV10: 0.5 | AW10: 0.396 | AX10: N/A | AY10: 0.64 | AZ10: 0.634 | BA10: 53.35 | BB10: 85.05 | BC10: 0.0017 | BD10: 0.82 | BE10: 0.2552 | BF10: 3.2698 | BG10: 79 | BH10: 0.0279 | BI10: N/A | BJ10: 0.84 | BK10: 2.2 | BL10: N/A | BM10: N/A | BN10: N/A | BO10: N/A | BP10: N/A | BQ10: N/A | BR10: 0.0096 | BS10: 2e-05 | BT10: 18 | BU10: 1 | BV10: 0.055555556 | BW10: 1 | BX10: 0.00059723708 | BY10: 2.7491195e-08 | BZ10: 1500 | CA10: 1500 | CB10: 190
A11: Ne | B11: [He]2s22p6 | C11: 20.1797 | D11: 10 | E11: 2 | F11: 18 | G11: 1 | H11: 3 | I11: 99 | J11: 9 | K11: 2 | L11: 6 | M11: 0 | N11: 0 | O11: 0 | P11: 0 | Q11: 10 | R11: 14 | S11: 8 | T11: 8 | U11: 8 | V11: N/A | W11: 0 | X11: 2.518 | Y11: 0.84 | Z11: 21.5645 | AA11: -1.2435079 | AB11: N/A | AC11: 11.3003 | AD11: N/A | AE11: N/A | AF11: N/A | AG11: N/A | AH11: 4.789 | AI11: 4.89 | AJ11: 13.37 | AK11: N/A | AL11: 98 | AM11: 0.38 | AN11: 0.69 | AO11: 1.14 | AP11: 1.02 | AQ11: 1.31 | AR11: 1.54 | AS11: 1.67 | AT11: 0.96 | AU11: 0.58 | AV11: 0.38 | AW11: 0.354 | AX11: N/A | AY11: N/A | AZ11: 0.396 | BA11: 24.45 | BB11: 25.15 | BC11: 0.0009 | BD11: 0.904 | BE11: 0.3317 | BF11: 1.7326 | BG11: 0 | BH11: 0.0493 | BI11: N/A | BJ11: 0.02 | BK11: N/A | BL11: N/A | BM11: N/A | BN11: N/A | BO11: N/A | BP11: N/A | BQ11: N/A | BR11: 0.04 | BS11: 0.00059 | BT11: 19 | BU11: 3 | BV11: 0.15789474 | BW11: 1 | BX11: 5.1045904e-09 | BY11: 0.00011218234 | BZ11: N/A | CA11: N/A | CB11: 33
A12: Na | B12: [Ne]3s1 | C12: 22.989768 | D12: 11 | E12: 3 | F12: 1 | G12: 0 | H12: 1 | I12: 2 | J12: 1 | K12: 1 | L12: 0 | M12: 0 | N12: 0 | O12: 1 | P12: 6 | Q12: 10 | R12: 14 | S12: 1 | T12: 1 | U12: 1 | V12: 1 | W12: 1 | X12: 1.842 | Y12: 2.584 | Z12: 5.1391 | AA12: 0.5491377 | AB12: 2.85 | AC12: 2.438 | AD12: 0.93 | AE12: 0.89 | AF12: 2.85 | AG12: 0.93 | AH12: 0.869 | AI12: 0.95 | AJ12: 2.64 | AK12: 0.9 | AL12: 1.08 | AM12: 1.9 | AN12: 1.54 | AO12: 1.16 | AP12: 0.72 | AQ12: 1.8 | AR12: 2.27 | AS12: 2.65 | AT12: 1.16 | AU12: 1.66 | AV12: 1.8 | AW12: 1.713 | AX12: 1.896 | AY12: 1.572 | AZ12: 23.6 | BA12: 370.95 | BB12: 1156.15 | BC12: 0.971 | BD12: 1.23 | BE12: 2.598 | BF12: 96.96 | BG12: 109 | BH12: 141 | BI12: 7e-05 | BJ12: 1.113 | BK12: 6.8 | BL12: 3.3 | BM12: 10 | BN12: N/A | BO12: 0.00069 | BP12: 4.7e-08 | BQ12: 21000000 | BR12: 0.53 | BS12: 0.0007 | BT12: 20 | BU12: 1 | BV12: 0.05 | BW12: 1 | BX12: 2.4093667e-10 | BY12: 1.8718797e-06 | BZ12: 1102 | CA12: 500 | CB12: 7
A13: Mg | B13: [Ne]3s2 | C13: 24.305 | D13: 12 | E13: 3 | F13: 2 | G13: 0 | H13: 1 | I13: 68 | J13: 2 | K13: 2 | L13: 0 | M13: 0 | N13: 0 | O13: 0 | P13: 6 | Q13: 10 | R13: 14 | S13: 2 | T13: 2 | U13: 2 | V13: 2 | W13: 2 | X13: 2.248 | Y13: 0.674 | Z13: 7.6462 | AA13: -0.41442818 | AB13: 3.75 | AC13: 3.6108 | AD13: 1.31 | AE13: 1.31 | AF13: 3.75 | AG13: 1.31 | AH13: 1.293 | AI13: 1.32 | AJ13: 3.93 | AK13: 1.2 | AL13: 2.35 | AM13: 1.45 | AN13: 1.3 | AO13: 0.86 | AP13: 0.54 | AQ13: 1.6 | AR13: 1.73 | AS13: 2.03 | AT13: 0.86 | AU13: 1.41 | AV13: 1.5 | AW13: 1.279 | AX13: 1.598 | AY13: 1.364 | AZ13: 10.6 | BA13: 922.15 | BB13: 1363.15 | BC13: 1.74 | BD13: 1.02 | BE13: 8.954 | BF13: 127.4 | BG13: 148 | BH13: 156 | BI13: 2.48e-05 | BJ13: 1.51 | BK13: 35.6 | BL13: 17 | BM13: 45 | BN13: N/A | BO13: 0.26 | BP13: 4.4e-08 | BQ13: 23000000 | BR13: 0.063 | BS13: 0.0001 | BT13: 22 | BU13: 3 | BV13: 0.13636364 | BW13: 1 | BX13: 0.023787391 | BY13: 3.502437e-05 | BZ13: 5259 | CA13: 500 | CB13: 3.7
A14: Al | B14: [Ne]3s23p1 | C14: 26.981539 | D14: 13 | E14: 3 | F14: 13 | G14: 1 | H14: 1 | I14: 73 | J14: 5 | K14: 2 | L14: 1 | M14: 0 | N14: 0 | O14: 0 | P14: 5 | Q14: 10 | R14: 14 | S14: 3 | T14: 3 | U14: 3 | V14: 3 | W14: 3 | X14: 1.989 | Y14: 0.761 | Z14: 5.9858 | AA14: 0.43495433 | AB14: 3.23 | AC14: 4.6393 | AD14: 1.61 | AE14: 1.64 | AF14: 3.23 | AG14: 1.61 | AH14: 1.613 | AI14: 1.55 | AJ14: 5.89 | AK14: 1.5 | AL14: 4.35 | AM14: 1.18 | AN14: 1.18 | AO14: 0.68 | AP14: 0.4 | AQ14: 1.41 | AR14: 1.84 | AS14: 1.68 | AT14: 0.53 | AU14: 1.21 | AV14: 1.25 | AW14: 1.312 | AX14: 1.429 | AY14: 1.248 | AZ14: 8.3 | BA14: 933.15 | BB14: 2740.15 | BC14: 2.7 | BD14: 0.9 | BE14: 10.79 | BF14: 293.4 | BG14: 326 | BH14: 237 | BI14: 2.31e-05 | BJ14: 3.39 | BK14: 75.2 | BL14: 26 | BM14: 70 | BN14: 0.167 | BO14: 0.245 | BP14: 2.6e-08 | BQ14: 38000000 | BR14: 0.233 | BS14: 0.03 | BT14: 22 | BU14: 1 | BV14: 0.045454545 | BW14: 1 | BX14: 0.084021558 | BY14: 2.7686862e-06 | BZ14: 1569 | CA14: 1000 | CB14: 1.8
A15: Si | B15: [Ne]3s23p2 | C15: 28.0855 | D15: 14 | E15: 3 | F15: 14 | G15: 1 | H15: 3 | I15: 78 | J15: 6 | K15: 2 | L15: 2 | M15: 0 | N15: 0 | O15: 0 | P15: 4 | Q15: 10 | R15: 14 | S15: 4 | T15: 4 | U15: 4 | V15: 4 | W15: 4 | X15: 2.321 | Y15: 0.652 | Z15: 8.1517 | AA15: 1.3879642 | AB15: 4.77 | AC15: 5.5236 | AD15: 1.9 | AE15: 1.98 | AF15: 4.77 | AG15: 1.9 | AH15: 1.916 | AI15: 1.87 | AJ15: 6.8 | AK15: 1.8 | AL15: 7.26 | AM15: 1.11 | AN15: 1.11 | AO15: 0.54 | AP15: 0.44 | AQ15: 1.1 | AR15: 2.1 | AS15: 1.42 | AT15: 0.4 | AU15: 0.11 | AV15: 1.1 | AW15: 1.068 | AX15: 1.316 | AY15: 1.173 | AZ15: 5.4 | BA15: 1683.15 | BB15: 2628.15 | BC15: 2.33 | BD15: 0.71 | BE15: 50.55 | BF15: 384.22 | BG15: 452 | BH15: 148 | BI15: 2.6e-06 | BJ15: 4.63 | BK15: 98 | BL15: 60 | BM15: 47 | BN15: 9.6301303 | BO15: 2.3 | BP15: 0.001 | BQ15: 1000 | BR15: 0.166 | BS15: 0.0002 | BT15: 23 | BU15: 3 | BV15: 0.13043478 | BW15: 1 | BX15: 0.2878989 | BY15: 3.2611145e-05 | BZ15: 4708 | CA15: 1000 | CB15: 5.4
A16: P | B16: [Ne]3s23p3 | C16: 30.973762 | D16: 15 | E16: 3 | F16: 15 | G16: 1 | H16: 3 | I16: 83 | J16: 7 | K16: 2 | L16: 3 | M16: 0 | N16: 0 | O16: 0 | P16: 3 | Q16: 10 | R16: 14 | S16: 5 | T16: 5 | U16: 5 | V16: 3 | W16: 3 | X16: 3.412 | Y16: 5.752 | Z16: 10.4867 | AA16: 0.74608933 | AB16: 5.62 | AC16: 6.3405 | AD16: 2.19 | AE16: 2.32 | AF16: 5.62 | AG16: 2.19 | AH16: 2.253 | AI16: 2.22 | AJ16: 8.33 | AK16: 2.1 | AL16: 11.2 | AM16: 0.98 | AN16: 1.06 | AO16: 0.58 | AP16: 1.84 | AQ16: 1.02 | AR16: 1.8 | AS16: 1.24 | AT16: 0.31 | AU16: 1.07 | AV16: 1 | AW16: 0.919 | AX16: 1.28 | AY16: 1.1 | AZ16: 3.6 | BA16: 317.25 | BB16: 553.15 | BC16: 1.82 | BD16: 0.77 | BE16: 0.657 | BF16: 12.129 | BG16: 315 | BH16: 0.235 | BI16: N/A | BJ16: 3.43 | BK16: 30.4 | BL16: N/A | BM16: N/A | BN16: N/A | BO16: N/A | BP16: 1e-07 | BQ16: 10000000 | BR16: 0.18 | BS16: 0.0002 | BT16: 23 | BU16: 1 | BV16: 0.043478261 | BW16: 1 | BX16: 0.001071964 | BY16: 3.3915591e-07 | BZ16: 1951 | CA16: 5063 | CB16: 4
A17: S | B17: [Ne]3s23p4 | C17: 32.066 | D17: 16 | E17: 3 | F17: 16 | G17: 1 | H17: 3 | I17: 88 | J17: 7 | K17: 2 | L17: 4 | M17: 0 | N17: 0 | O17: 0 | P17: 2 | Q17: 10 | R17: 14 | S17: 6 | T17: 6 | U17: 6 | V17: 2 | W17: 2 | X17: 2.617 | Y17: 5.787 | Z17: 10.36 | AA17: 2.072 | AB17: 6.22 | AC17: 6.8379 | AD17: 2.58 | AE17: 2.65 | AF17: 6.22 | AG17: 2.58 | AH17: 2.589 | AI17: 2.49 | AJ17: 11.88 | AK17: 2.53 | AL17: 16.4 | AM17: 0.88 | AN17: 1.02 | AO17: 1.7 | AP17: 1.81 | AQ17: 1.03 | AR17: 1.8 | AS17: 1.1 | AT17: 0.43 | AU17: 1.05 | AV17: 1 | AW17: 0.81 | AX17: 1.27 | AY17: 1.04 | AZ17: 2.9 | BA17: 385.95 | BB17: 717.85 | BC17: 2.07 | BD17: 0.71 | BE17: 1.7175 | BF17: 9.8 | BG17: 279 | BH17: 0.269 | BI17: N/A | BJ17: 2.85 | BK17: 7.7 | BL17: N/A | BM17: N/A | BN17: N/A | BO17: N/A | BP17: 1e+15 | BQ17: 1e-15 | BR17: 0.52 | BS17: 0.00055 | BT17: 24 | BU17: 4 | BV17: 0.16666667 | BW17: 1 | BX17: 0.00035732133 | BY17: 1.679474e-05 | BZ17: 737 | CA17: 1000 | CB17: 24
A18: Cl | B18: [Ne]3s23p5 | C18: 35.4527 | D18: 17 | E18: 3 | F18: 17 | G18: 1 | H18: 3 | I18: 94 | J18: 8 | K18: 2 | L18: 5 | M18: 0 | N18: 0 | O18: 0 | P18: 1 | Q18: 10 | R18: 14 | S18: 7 | T18: 7 | U18: 7 | V18: 1 | W18: 0 | X18: 2.928 | Y18: 0.517 | Z18: 12.9676 | AA18: 3.6176598 | AB18: 8.3 | AC18: 7.2923 | AD18: 3.16 | AE18: 2.98 | AF18: 8.3 | AG18: 3.16 | AH18: 2.869 | AI18: 2.82 | AJ18: 14.06 | AK18: 2.97 | AL18: 23 | AM18: 0.79 | AN18: 0.99 | AO18: 1.67 | AP18: 1.38 | AQ18: 1.05 | AR18: 1.75 | AS18: 1.01 | AT18: 1.67 | AU18: 1.02 | AV18: 1 | AW18: 0.725 | AX18: N/A | AY18: 0.994 | AZ18: 2.2 | BA18: 172.15 | BB18: 238.55 | BC18: 0.00321 | BD18: 0.48 | BE18: 3.23 | BF18: 10.2 | BG18: 121 | BH18: 0.0089 | BI18: N/A | BJ18: 1.4 | BK18: 1.1 | BL18: N/A | BM18: N/A | BN18: N/A | BO18: N/A | BP18: 100 | BQ18: 0.01 | BR18: 35.3 | BS18: 0.033 | BT18: 24 | BU18: 2 | BV18: 0.083333333 | BW18: 1 | BX18: 0.00014803312 | BY18: 1.708824e-07 | BZ18: 1500 | CA18: 1500 | CB18: 0.15
A19: Ar | B19: [Ne]3s23p6 | C19: 39.948 | D19: 18 | E19: 3 | F19: 18 | G19: 1 | H19: 3 | I19: 100 | J19: 9 | K19: 2 | L19: 6 | M19: 0 | N19: 0 | O19: 0 | P19: 0 | Q19: 10 | R19: 14 | S19: 8 | T19: 8 | U19: 8 | V19: N/A | W19: 0 | X19: 3.228 | Y19: 0.469 | Z19: 15.7596 | AA19: -0.99468876 | AB19: N/A | AC19: 7.6515 | AD19: N/A | AE19: N/A | AF19: N/A | AG19: N/A | AH19: 3.242 | AI19: 3.18 | AJ19: 12.55 | AK19: N/A | AL19: 31.2 | AM19: 0.71 | AN19: 0.97 | AO19: 1.88 | AP19: 1.3 | AQ19: 1.75 | AR19: 1.88 | AS19: 2.57 | AT19: 1.88 | AU19: 1.06 | AV19: 0.71 | AW19: 0.659 | AX19: N/A | AY19: N/A | AZ19: 1.586 | BA19: 83.95 | BB19: 87.45 | BC19: 0.00178 | BD19: 0.52 | BE19: 1.188 | BF19: 6.447 | BG19: 0 | BH19: 0.01772 | BI19: N/A | BJ19: 0.08 | BK19: N/A | BL19: N/A | BM19: N/A | BN19: N/A | BO19: N/A | BP19: N/A | BQ19: N/A | BR19: 0.66 | BS19: 0.00059 | BT19: 24 | BU19: 3 | BV19: 0.125 | BW19: 1 | BX19: 3.5732133e-06 | BY19: 3.2937257e-06 | BZ19: N/A | CA19: N/A | CB19: 0.5
A20: K | B20: [Ar]4s1 | C20: 39.0983 | D20: 19 | E20: 4 | F20: 1 | G20: 0 | H20: 1 | I20: 3 | J20: 1 | K20: 1 | L20: 0 | M20: 0 | N20: 0 | O20: 1 | P20: 6 | Q20: 10 | R20: 14 | S20: 1 | T20: 1 | U20: 1 | V20: 1 | W20: 1 | X20: 1.694 | Y20: 0.894 | Z20: 4.3407 | AA20: 0.49726396 | AB20: 2.42 | AC20: 2.0027 | AD20: 0.82 | AE20: 0.8 | AF20: 2.42 | AG20: 0.82 | AH20: 0.734 | AI20: 0.84 | AJ20: 2.48 | AK20: 0.8 | AL20: 0.467 | AM20: 2.43 | AN20: 1.96 | AO20: 1.52 | AP20: 1.38 | AQ20: 2.3 | AR20: 2.75 | AS20: 3.69 | AT20: 1.52 | AU20: 2.03 | AV20: 2.2 | AW20: 2.162 | AX20: 2.349 | AY20: 2.025 | AZ20: 43.4 | BA20: 336.4 | BB20: 1033.15 | BC20: 0.86 | BD20: 0.75 | BE20: 2.334 | BF20: 79.87 | BG20: 90 | BH20: 102.4 | BI20: 8.3e-05 | BJ20: 0.934 | BK20: 3.2 | BL20: 1.3 | BM20: 3.53 | BN20: N/A | BO20: 0.000363 | BP20: 7e-08 | BQ20: 14000000 | BR20: 2.1 | BS20: 0.0018 | BT20: 24 | BU20: 2 | BV20: 0.083333333 | BW20: 0.999883 | BX20: 0.021337188 | BY20: 1.2294402e-07 | BZ20: 1738 | CA20: 7201 | CB20: 85
A21: Ca | B21: [Ar]4s2 | C21: 40.078 | D21: 20 | E21: 4 | F21: 2 | G21: 0 | H21: 1 | I21: 7 | J21: 2 | K21: 2 | L21: 0 | M21: 0 | N21: 0 | O21: 0 | P21: 6 | Q21: 10 | R21: 14 | S21: 2 | T21: 2 | U21: 2 | V21: 2 | W21: 2 | X21: 2.68 | Y21: 1.004 | Z21: 6.1132 | AA21: 0.020722712 | AB21: 2.2 | AC21: 2.6965 | AD21: 1 | AE21: 1.17 | AF21: 2.2 | AG21: 1 | AH21: 1.034 | AI21: 1.11 | AJ21: 2.19 | AK21: 1 | AL21: 1.02 | AM21: 1.94 | AN21: 1.74 | AO21: 1.14 | AP21: 1 | AQ21: 2.01 | AR21: 2.31 | AS21: 3 | AT21: 1.14 | AU21: 1.76 | AV21: 1.8 | AW21: 1.69 | AX21: 1.97 | AY21: 1.736 | AZ21: 22.8 | BA21: 1112.15 | BB21: 1757.15 | BC21: 1.55 | BD21: 0.63 | BE21: 8.54 | BF21: 153.3 | BG21: 178 | BH21: 200 | BI21: 2.23e-05 | BJ21: 1.84 | BK21: 17.2 | BL21: 7.4 | BM21: 20 | BN21: N/A | BO21: 0.167 | BP21: 3.4e-08 | BQ21: 29000000 | BR21: 0.43 | BS21: 0.00037 | BT21: 24 | BU21: 5 | BV21: 0.20833333 | BW21: 0.99813 | BX21: 0.0423681 | BY21: 1.992541e-06 | BZ21: 3860 | CA21: 1500 | CB21: 11
A22: Sc | B22: [Ar]4s23d1 | C22: 44.95591 | D22: 21 | E22: 4 | F22: 3 | G22: 2 | H22: 1 | I22: 11 | J22: 3 | K22: 2 | L22: 0 | M22: 1 | N22: 0 | O22: 0 | P22: 6 | Q22: 9 | R22: 14 | S22: 3 | T22: 2 | U22: 1 | V22: 3 | W22: 3 | X22: 2.777 | Y22: 0.969 | Z22: 6.5615 | AA22: 0.18658294 | AB22: 3.34 | AC22: 2.8571 | AD22: 1.36 | AE22: 1.5 | AF22: 3.34 | AG22: 1.36 | AH22: 1.19 | AI22: 1.17 | AJ22: 1.83 | AK22: 1.3 | AL22: 1.18 | AM22: 1.84 | AN22: 1.44 | AO22: 0.89 | AP22: 0.75 | AQ22: 1.62 | AR22: 2.3 | AS22: 2.75 | AT22: 0.89 | AU22: 1.7 | AV22: 1.6 | AW22: 1.57 | AX22: 1.62 | AY22: 1.439 | AZ22: 17.8 | BA22: 1814.15 | BB22: 3105.15 | BC22: 2.99 | BD22: 0.6 | BE22: 14.1 | BF22: 314.2 | BG22: 378 | BH22: 15.8 | BI22: 1.02e-05 | BJ22: 3.9 | BK22: 56.6 | BL22: 29 | BM22: 74 | BN22: N/A | BO22: 0.75 | BP22: 5.5e-07 | BQ22: 1800000 | BR22: 27.2 | BS22: 0.025 | BT22: 25 | BU22: 1 | BV22: 0.04 | BW22: 1 | BX22: 2.2460198e-05 | BY22: 1.1153012e-09 | BZ22: 5500 | CA22: 4500 | CB22: 1400
A23: Ti | B23: [Ar]4s23d2 | C23: 47.867 | D23: 22 | E23: 4 | F23: 4 | G23: 2 | H23: 1 | I23: 43 | J23: 4 | K23: 2 | L23: 0 | M23: 2 | N23: 0 | O23: 0 | P23: 6 | Q23: 8 | R23: 14 | S23: 4 | T23: 2 | U23: 2 | V23: 4 | W23: 4 | X23: 2.833 | Y23: 0.95 | Z23: 6.8281 | AA23: 0.08289044 | AB23: 3.45 | AC23: 3.004 | AD23: 1.54 | AE23: 1.86 | AF23: 3.45 | AG23: 1.54 | AH23: 1.38 | AI23: 1.23 | AJ23: 2.28 | AK23: 1.6 | AL23: 1.37 | AM23: 1.76 | AN23: 1.36 | AO23: 1 | AP23: 0.86 | AQ23: 1.42 | AR23: 2.15 | AS23: 2.58 | AT23: 0.75 | AU23: 1.6 | AV23: 1.4 | AW23: 1.477 | AX23: 1.467 | AY23: 1.324 | AZ23: 14.6 | BA23: 1933.15 | BB23: 3560.15 | BC23: 4.54 | BD23: 0.52 | BE23: 15.45 | BF23: 421 | BG23: 470 | BH23: 21.9 | BI23: 8.6e-06 | BJ23: 4.85 | BK23: 108 | BL23: 44 | BM23: 116 | BN23: 0.97 | BO23: 0.715 | BP23: 4e-07 | BQ23: 2500000 | BR23: 6.1 | BS23: 0.0044 | BT23: 26 | BU23: 5 | BV23: 0.19230769 | BW23: 1 | BX23: 0.0057681871 | BY23: 7.8266748e-08 | BZ23: 1119 | CA23: 1552 | CB23: 6.1
A24: V | B24: [Ar]4s23d3 | C24: 50.9415 | D24: 23 | E24: 4 | F24: 5 | G24: 2 | H24: 1 | I24: 46 | J24: 4 | K24: 2 | L24: 0 | M24: 3 | N24: 0 | O24: 0 | P24: 6 | Q24: 7 | R24: 14 | S24: 5 | T24: 2 | U24: 3 | V24: 5 | W24: 5 | X24: 2.816 | Y24: 0.956 | Z24: 6.7462 | AA24: 0.52850415 | AB24: 3.6 | AC24: 3.1482 | AD24: 1.63 | AE24: 2.22 | AF24: 3.6 | AG24: 1.63 | AH24: 1.53 | AI24: 1.27 | AJ24: 2.42 | AK24: 1.9 | AL24: 1.58 | AM24: 1.71 | AN24: 1.25 | AO24: 0.93 | AP24: 0.79 | AQ24: 1.34 | AR24: 2.05 | AS24: 2.43 | AT24: 0.68 | AU24: 1.53 | AV24: 1.35 | AW24: 1.401 | AX24: 1.338 | AY24: 1.224 | AZ24: 12.4 | BA24: 2163.15 | BB24: 3653.15 | BC24: 6.11 | BD24: 0.49 | BE24: 20.9 | BF24: 453 | BG24: 514 | BH24: 30.7 | BI24: 8.4e-06 | BJ24: 5.31 | BK24: 158 | BL24: 47 | BM24: 128 | BN24: 0.628 | BO24: 0.628 | BP24: 2e-07 | BQ24: 5000000 | BR24: 5.06 | BS24: 0.0033 | BT24: 26 | BU24: 1 | BV24: 0.038461538 | BW24: 0.9975 | BX24: 0.00012251017 | BY24: 9.5550655e-09 | BZ24: 3266 | CA24: 3397 | CB24: 220
A25: Cr | B25: [Ar]4s13d5 | C25: 51.9961 | D25: 24 | E25: 4 | F25: 6 | G25: 2 | H25: 1 | I25: 49 | J25: 4 | K25: 1 | L25: 0 | M25: 5 | N25: 0 | O25: 1 | P25: 6 | Q25: 5 | R25: 14 | S25: 6 | T25: 1 | U25: 4 | V25: 2.9 | W25: 5.78 | X25: 2.82 | Y25: 0.955 | Z25: 6.7665 | AA25: 0.67354135 | AB25: 3.72 | AC25: 3.2951 | AD25: 1.66 | AE25: 2 | AF25: 3.72 | AG25: 1.66 | AH25: 1.65 | AI25: 1.29 | AJ25: 2.72 | AK25: 2.2 | AL25: 1.8 | AM25: 1.66 | AN25: 1.27 | AO25: 0.87 | AP25: 0.8 | AQ25: 1.3 | AR25: 2 | AS25: 2.44 | AT25: 0.76 | AU25: 1.39 | AV25: 1.4 | AW25: 1.453 | AX25: 1.357 | AY25: 1.172 | AZ25: 11.6 | BA25: 2130.15 | BB25: 2945.15 | BC25: 7.19 | BD25: 0.45 | BE25: 16.9 | BF25: 344.3 | BG25: 397 | BH25: 93.7 | BI25: 4.9e-06 | BJ25: 4.1 | BK25: 160 | BL25: 115 | BM25: 279 | BN25: 1.06 | BO25: 1.12 | BP25: 1.3e-07 | BQ25: 7900000 | BR25: 3.1 | BS25: 0.0021 | BT25: 26 | BU25: 4 | BV25: 0.15384615 | BW25: 1 | BX25: 0.00010413364 | BY25: 4.4025046e-07 | BZ25: 3103 | CA25: 4053 | CB25: 10
A26: Mn | B26: [Ar]4s23d5 | C26: 54.93805 | D26: 25 | E26: 4 | F26: 7 | G26: 2 | H26: 1 | I26: 52 | J26: 4 | K26: 2 | L26: 0 | M26: 5 | N26: 0 | O26: 0 | P26: 6 | Q26: 5 | R26: 14 | S26: 7 | T26: 2 | U26: 5 | V26: 4.16 | W26: 5.78 | X26: 2.956 | Y26: 0.911 | Z26: 7.434 | AA26: -0.51841004 | AB26: 3.72 | AC26: 3.4349 | AD26: 1.55 | AE26: 2.04 | AF26: 3.72 | AG26: 1.55 | AH26: 1.75 | AI26: 1.36 | AJ26: 2.01 | AK26: 2.6 | AL26: 2.05 | AM26: 1.61 | AN26: 1.39 | AO26: 0.81 | AP26: 0.83 | AQ26: 1.32 | AR26: 1.96 | AS26: 2.22 | AT26: 0.81 | AU26: 1.32 | AV26: 1.4 | AW26: 1.278 | AX26: 1.306 | AY26: 1.168 | AZ26: 9.4 | BA26: 1517.15 | BB26: 2235.15 | BC26: 7.43 | BD26: 0.48 | BE26: 12.05 | BF26: 226 | BG26: 281 | BH26: 7.82 | BI26: 2.17e-05 | BJ26: 2.92 | BK26: 92.6 | BL26: 76.4 | BM26: 198 | BN26: N/A | BO26: 0.196 | BP26: 1.6e-06 | BQ26: 620000 | BR26: 13.3 | BS26: 0.0083 | BT26: 26 | BU26: 1 | BV26: 0.038461538 | BW26: 1 | BX26: 0.00096987217 | BY26: 3.1143644e-07 | BZ26: 1593 | CA26: 1790 | CB26: 1.7
A27: Fe | B27: [Ar]4s23d6 | C27: 55.847 | D27: 26 | E27: 4 | F27: 8 | G27: 2 | H27: 1 | I27: 55 | J27: 4 | K27: 2 | L27: 0 | M27: 6 | N27: 0 | O27: 0 | P27: 6 | Q27: 4 | R27: 14 | S27: 8 | T27: 2 | U27: 5 | V27: 5.78 | W27: 5.78 | X27: 3.0478 | Y27: 2.777 | Z27: 7.9024 | AA27: 0.15555906 | AB27: 4.06 | AC27: 3.5836 | AD27: 1.83 | AE27: 1.67 | AF27: 4.06 | AG27: 1.83 | AH27: 1.8 | AI27: 1.4 | AJ27: 3.9 | AK27: 2.76 | AL27: 2.31 | AM27: 1.56 | AN27: 1.25 | AO27: 0.75 | AP27: 0.78 | AQ27: 1.25 | AR27: 1.59 | AS27: 2.11 | AT27: 0.69 | AU27: 1.32 | AV27: 1.4 | AW27: 1.227 | AX27: 1.26 | AY27: 1.165 | AZ27: 8.4 | BA27: 1808.15 | BB27: 3023.15 | BC27: 7.86 | BD27: 0.44 | BE27: 13.8 | BF27: 349.6 | BG27: 418 | BH27: 80.2 | BI27: 1.18e-05 | BJ27: 4.28 | BK27: 166 | BL27: 82 | BM27: 211 | BN27: 0.608 | BO27: 0.49 | BP27: 9.7e-08 | BQ27: 10000000 | BR27: 2.56 | BS27: 0.0015 | BT27: 28 | BU27: 4 | BV27: 0.14285714 | BW27: 1 | BX27: 0.057477688 | BY27: 2.9350031e-05 | BZ27: 2424 | CA27: 1373 | CB27: 6.7
A28: Co | B28: [Ar]4s23d7 | C28: 58.9332 | D28: 27 | E28: 4 | F28: 9 | G28: 2 | H28: 1 | I28: 58 | J28: 4 | K28: 2 | L28: 0 | M28: 7 | N28: 0 | O28: 0 | P28: 6 | Q28: 3 | R28: 14 | S28: 9 | T28: 2 | U28: 4 | V28: 5.78 | W28: 5.78 | X28: 3.046 | Y28: 0.885 | Z28: 7.881 | AA28: 0.66366316 | AB28: 4.3 | AC28: 3.7305 | AD28: 1.88 | AE28: 1.72 | AF28: 4.3 | AG28: 1.88 | AH28: 1.84 | AI28: 1.44 | AJ28: 3.03 | AK28: 3.13 | AL28: 2.6 | AM28: 1.52 | AN28: 1.26 | AO28: 0.79 | AP28: 0.75 | AQ28: 1.25 | AR28: 2 | AS28: 2.02 | AT28: 0.54 | AU28: 1.26 | AV28: 1.35 | AW28: 1.181 | AX28: 1.252 | AY28: 1.157 | AZ28: 7.5 | BA28: 1768.15 | BB28: 3143.15 | BC28: 8.9 | BD28: 0.42 | BE28: 16.19 | BF28: 376.5 | BG28: 425 | BH28: 100 | BI28: 1.3e-05 | BJ28: 4.39 | BK28: 182 | BL28: 76 | BM28: 209 | BN28: 1.043 | BO28: 0.7 | BP28: 6e-08 | BQ28: 17000000 | BR28: 37.2 | BS28: 0.021 | BT28: 29 | BU28: 1 | BV28: 0.034482759 | BW28: 1 | BX28: 2.5522952e-05 | BY28: 7.3375077e-08 | BZ28: 3052 | CA28: 2655 | CB28: 21
A29: Ni | B29: [Ar]4s23d8 | C29: 58.6934 | D29: 28 | E29: 4 | F29: 10 | G29: 2 | H29: 1 | I29: 61 | J29: 4 | K29: 2 | L29: 0 | M29: 8 | N29: 0 | O29: 0 | P29: 6 | Q29: 2 | R29: 14 | S29: 10 | T29: 2 | U29: 3 | V29: 5.78 | W29: 5.78 | X29: 2.996 | Y29: 0.898 | Z29: 7.6398 | AA29: 1.1610008 | AB29: 4.4 | AC29: 3.8584 | AD29: 1.91 | AE29: 1.76 | AF29: 4.4 | AG29: 1.91 | AH29: 1.88 | AI29: 1.47 | AJ29: 3.48 | AK29: 3.33 | AL29: 2.92 | AM29: 1.49 | AN29: 1.21 | AO29: 0.74 | AP29: 0.6 | AQ29: 1.28 | AR29: 1.63 | AS29: 2.18 | AT29: 0.7 | AU29: 1.24 | AV29: 1.35 | AW29: 1.139 | AX29: 1.244 | AY29: 1.149 | AZ29: 6.8 | BA29: 1726.15 | BB29: 3003.15 | BC29: 8.9 | BD29: 0.44 | BE29: 17.47 | BF29: 370.4 | BG29: 430 | BH29: 90.7 | BI29: 1.34e-05 | BJ29: 4.44 | BK29: 177 | BL29: 76 | BM29: 200 | BN29: 0.638 | BO29: 0.7 | BP29: 7e-08 | BQ29: 14000000 | BR29: 4.5 | BS29: 0.0026 | BT29: 31 | BU29: 5 | BV29: 0.16129032 | BW29: 1 | BX29: 8.5757119e-05 | BY29: 1.6077295e-06 | BZ29: 988 | CA29: 1479 | CB29: 7.7
A30: Cu | B30: [Ar]4s13d10 | C30: 63.546 | D30: 29 | E30: 4 | F30: 11 | G30: 2 | H30: 1 | I30: 64 | J30: 4 | K30: 1 | L30: 0 | M30: 10 | N30: 0 | O30: 1 | P30: 6 | Q30: 0 | R30: 14 | S30: 11 | T30: 1 | U30: 2 | V30: 5.44 | W30: 5.44 | X30: 3.013 | Y30: 0.893 | Z30: 7.7264 | AA30: 1.2341498 | AB30: 4.48 | AC30: 4.0026 | AD30: 1.9 | AE30: 1.08 | AF30: 4.48 | AG30: 1.9 | AH30: 1.85 | AI30: 1.51 | AJ30: 2.91 | AK30: 2.2 | AL30: 3.25 | AM30: 1.45 | AN30: 1.38 | AO30: 0.87 | AP30: 0.77 | AQ30: 1.27 | AR30: 1.4 | AS30: 2.04 | AT30: 0.71 | AU30: 1.32 | AV30: 1.35 | AW30: 1.191 | AX30: 1.276 | AY30: 1.173 | AZ30: 6.7 | BA30: 1356.15 | BB30: 2840.15 | BC30: 8.96 | BD30: 0.38 | BE30: 13.05 | BF30: 300.3 | BG30: 338 | BH30: 401 | BI30: 1.65e-05 | BJ30: 3.49 | BK30: 138 | BL30: 48 | BM30: 130 | BN30: 0.369 | BO30: 0.874 | BP30: 1.7e-08 | BQ30: 59000000 | BR30: 3.78 | BS30: 0.0021 | BT30: 29 | BU30: 2 | BV30: 0.068965517 | BW30: 1 | BX30: 6.1255085e-05 | BY30: 1.7023018e-08 | BZ30: 1576 | CA30: 1524 | CB30: 2.7
A31: Zn | B31: [Ar]4s23d10 | C31: 65.38 | D31: 30 | E31: 4 | F31: 12 | G31: 2 | H31: 1 | I31: 69 | J31: 4 | K31: 2 | L31: 0 | M31: 10 | N31: 0 | O31: 0 | P31: 6 | Q31: 0 | R31: 14 | S31: 12 | T31: 2 | U31: 1 | V31: 4.44 | W31: 4.44 | X31: 3.322 | Y31: 0.81 | Z31: 9.3942 | AA31: -0.62213245 | AB31: 4.45 | AC31: 4.1332 | AD31: 1.65 | AE31: 1.44 | AF31: 4.45 | AG31: 1.65 | AH31: 1.59 | AI31: 1.46 | AJ31: 3.13 | AK31: 1.2 | AL31: 3.61 | AM31: 1.42 | AN31: 1.31 | AO31: 0.88 | AP31: 0.74 | AQ31: 1.4 | AR31: 1.39 | AS31: 1.88 | AT31: 0.74 | AU31: 1.22 | AV31: 1.35 | AW31: 1.065 | AX31: 1.379 | AY31: 1.249 | AZ31: 6.4 | BA31: 692.75 | BB31: 1179.15 | BC31: 7.13 | BD31: 0.39 | BE31: 7.322 | BF31: 115.3 | BG31: 131 | BH31: 116 | BI31: 3.02e-05 | BJ31: 1.35 | BK31: 69.4 | BL31: 43 | BM31: 108 | BN31: 8.012033 | BO31: 0.412 | BP31: 5.9e-08 | BQ31: 17000000 | BR31: 1.1 | BS31: 0.00055 | BT31: 30 | BU31: 5 | BV31: 0.16666667 | BW31: 1 | BX31: 7.1464265e-05 | BY31: 4.1090043e-08 | BZ31: 1574 | CA31: 1895 | CB31: 3.7
A32: Ga | B32: [Ar]4s23d104p1 | C32: 69.723 | D32: 31 | E32: 4 | F32: 13 | G32: 1 | H32: 1 | I32: 74 | J32: 5 | K32: 2 | L32: 1 | M32: 10 | N32: 0 | O32: 0 | P32: 5 | Q32: 0 | R32: 14 | S32: 13 | T32: 3 | U32: 3 | V32: 3.44 | W32: 3.44 | X32: 2.655 | Y32: 1.014 | Z32: 5.9993 | AA32: 0.4248209 | AB32: 3.2 | AC32: 4.6638 | AD32: 1.81 | AE32: 1.7 | AF32: 3.2 | AG32: 1.81 | AH32: 1.756 | AI32: 1.56 | AJ32: 3.3 | AK32: 1.4 | AL32: 5.49 | AM32: 1.36 | AN32: 1.26 | AO32: 0.76 | AP32: 0.62 | AQ32: 1.34 | AR32: 1.87 | AS32: 1.7 | AT32: 0.76 | AU32: 1.22 | AV32: 1.3 | AW32: 1.254 | AX32: 1.408 | AY32: 1.245 | AZ32: 8.1 | BA32: 302.95 | BB32: 2676.15 | BC32: 5.9 | BD32: 0.37 | BE32: 5.59 | BF32: 258.7 | BG32: 286 | BH32: 40.6 | BI32: 1.2e-06 | BJ32: 2.81 | BK32: 56.9 | BL32: N/A | BM32: N/A | BN32: N/A | BO32: 0.06 | BP32: 1.4e-07 | BQ32: 7100000 | BR32: 2.9 | BS32: 0.0015 | BT32: 31 | BU32: 2 | BV32: 0.064516129 | BW32: 1 | BX32: 1.9397443e-05 | BY32: 1.2327013e-09 | BZ32: 5500 | CA32: 1895 | CB32: 220
A33: Ge | B33: [Ar]4s23d104p2 | C33: 72.63 | D33: 32 | E33: 4 | F33: 14 | G33: 1 | H33: 2 | I33: 79 | J33: 6 | K33: 2 | L33: 2 | M33: 10 | N33: 0 | O33: 0 | P33: 4 | Q33: 0 | R33: 14 | S33: 14 | T33: 4 | U33: 4 | V33: 4 | W33: 4 | X33: 3.046 | Y33: 0.884 | Z33: 7.8994 | AA33: 1.2336333 | AB33: 4.6 | AC33: 5.1318 | AD33: 2.01 | AE33: 1.99 | AF33: 4.6 | AG33: 2.01 | AH33: 1.994 | AI33: 1.81 | AJ33: 4.24 | AK33: 1.7 | AL33: 7.92 | AM33: 1.25 | AN33: 1.22 | AO33: 0.87 | AP33: 0.73 | AQ33: 1.14 | AR33: 2.11 | AS33: 1.56 | AT33: 0.53 | AU33: 1.2 | AV33: 1.25 | AW33: 1.09 | AX33: 1.366 | AY33: 1.223 | AZ33: 6.1 | BA33: 1220.55 | BB33: 3103.15 | BC33: 5.32 | BD33: 0.32 | BE33: 36.94 | BF33: 330.9 | BG33: 377 | BH33: 59.9 | BI33: 6e-06 | BJ33: 3.85 | BK33: 77.2 | BL33: N/A | BM33: N/A | BN33: N/A | BO33: 7.2734025 | BP33: 0.0005 | BQ33: 2000 | BR33: 2.2 | BS33: 0.0011 | BT33: 32 | BU33: 4 | BV33: 0.125 | BW33: 0.9239 | BX33: 1.5313771e-06 | BY33: 3.8807263e-09 | BZ33: 5267 | CA33: 1895 | CB33: 360
A34: As | B34: [Ar]4s23d104p3 | C34: 74.92159 | D34: 33 | E34: 4 | F34: 15 | G34: 1 | H34: 2 | I34: 84 | J34: 6 | K34: 2 | L34: 3 | M34: 10 | N34: 0 | O34: 0 | P34: 3 | Q34: 0 | R34: 14 | S34: 15 | T34: 5 | U34: 5 | V34: 3 | W34: 3 | X34: 3.396 | Y34: 0.884 | Z34: 9.7886 | AA34: 0.80624161 | AB34: 5.3 | AC34: 5.5372 | AD34: 2.18 | AE34: 2.27 | AF34: 5.3 | AG34: 2.18 | AH34: 2.211 | AI34: 2.11 | AJ34: 4.94 | AK34: 2 | AL34: 11.1 | AM34: 1.14 | AN34: 1.19 | AO34: 0.72 | AP34: 0.58 | AQ34: 1.15 | AR34: 1.85 | AS34: 1.42 | AT34: 0.72 | AU34: 1.19 | AV34: 1.15 | AW34: 1.001 | AX34: 1.39 | AY34: 1.21 | AZ34: 4.3 | BA34: 1090.15 | BB34: 890.15 | BC34: 5.73 | BD34: 0.33 | BE34: 27.7 | BF34: 34.76 | BG34: 302 | BH34: 50 | BI34: N/A | BJ34: 2.96 | BK34: 38.3 | BL34: N/A | BM34: 8 | BN34: N/A | BO34: 1.44 | BP34: 3e-07 | BQ34: 3300000 | BR34: 4.2 | BS34: 0.002 | BT34: 33 | BU34: 1 | BV34: 0.03030303 | BW34: 1 | BX34: 1.8376525e-06 | BY34: 2.1392911e-10 | BZ34: 3337 | CA34: 4000 | CB34: 320
A35: Se | B35: [Ar]4s23d104p4 | C35: 78.971 | D35: 34 | E35: 4 | F35: 16 | G35: 1 | H35: 3 | I35: 89 | J35: 7 | K35: 2 | L35: 4 | M35: 10 | N35: 0 | O35: 0 | P35: 2 | Q35: 0 | R35: 14 | S35: 16 | T35: 6 | U35: 6 | V35: 2 | W35: 2 | X35: 3.385 | Y35: 0.795 | Z35: 9.7524 | AA35: 2.0209543 | AB35: 5.89 | AC35: 5.8746 | AD35: 2.55 | AE35: 2.54 | AF35: 5.89 | AG35: 2.55 | AH35: 2.434 | AI35: 2.31 | AJ35: 4.82 | AK35: 2.4 | AL35: 14.7 | AM35: 1.03 | AN35: 1.16 | AO35: 1.84 | AP35: 1.98 | AQ35: 1.18 | AR35: 1.9 | AS35: 1.29 | AT35: 0.56 | AU35: 1.2 | AV35: 1.15 | AW35: 0.918 | AX35: 1.4 | AY35: 1.17 | AZ35: 3.8 | BA35: 490.15 | BB35: 958.15 | BC35: 4.79 | BD35: 0.32 | BE35: 6.694 | BF35: 37.7 | BG35: 227 | BH35: 0.52 | BI35: N/A | BJ35: 2.46 | BK35: 8.3 | BL35: 3.7 | BM35: 10 | BN35: N/A | BO35: 0.736 | BP35: N/A | BQ35: N/A | BR35: 11.7 | BS35: 0.0056 | BT35: 30 | BU35: 5 | BV35: 0.16666667 | BW35: 0.9127 | BX35: 5.1045904e-08 | BY35: 2.0251521e-09 | BZ35: 2225 | CA35: 1910 | CB35: 14
A36: Br | B36: [Ar]4s23d104p5 | C36: 79.904 | D36: 35 | E36: 4 | F36: 17 | G36: 1 | H36: 3 | I36: 95 | J36: 8 | K36: 2 | L36: 5 | M36: 10 | N36: 0 | O36: 0 | P36: 1 | Q36: 0 | R36: 14 | S36: 17 | T36: 7 | U36: 7 | V36: 1 | W36: 0 | X36: 3.726 | Y36: 0.723 | Z36: 11.8138 | AA36: 3.3679693 | AB36: 7.59 | AC36: 6.1658 | AD36: 2.96 | AE36: 2.83 | AF36: 7.59 | AG36: 2.96 | AH36: 2.685 | AI36: 2.56 | AJ36: 7.35 | AK36: 2.75 | AL36: 19.3 | AM36: 0.94 | AN36: 1.14 | AO36: 1.82 | AP36: 1.96 | AQ36: 1.2 | AR36: 1.85 | AS36: 1.2 | AT36: 1.82 | AU36: 1.2 | AV36: 1.15 | AW36: 0.851 | AX36: N/A | AY36: 1.142 | AZ36: 3.1 | BA36: 265.95 | BB36: 331.95 | BC36: 3.12 | BD36: 0.473 | BE36: 5.286 | BF36: 15.438 | BG36: 112 | BH36: 0.122 | BI36: N/A | BJ36: 1.22 | BK36: 1.9 | BL36: N/A | BM36: N/A | BN36: N/A | BO36: N/A | BP36: 10000000000 | BQ36: 1e-10 | BR36: 6.8 | BS36: 0.002 | BT36: 31 | BU36: 2 | BV36: 0.064516129 | BW36: 1 | BX36: 2.4502034e-06 | BY36: 3.8481151e-10 | BZ36: 3299 | CA36: 6880 | CB36: 4.9
A37: Kr | B37: [Ar]4s23d104p6 | C37: 83.798 | D37: 36 | E37: 4 | F37: 18 | G37: 1 | H37: 3 | I37: 101 | J37: 9 | K37: 2 | L37: 6 | M37: 10 | N37: 0 | O37: 0 | P37: 0 | Q37: 0 | R37: 14 | S37: 18 | T37: 8 | U37: 8 | V37: N/A | W37: 0 | X37: 4.056 | Y37: 0.664 | Z37: 13.9996 | AA37: -0.62174389 | AB37: N/A | AC37: 6.3916 | AD37: 3 | AE37: N/A | AF37: N/A | AG37: N/A | AH37: 2.966 | AI37: 2.82 | AJ37: 9.59 | AK37: N/A | AL37: 24.6 | AM37: 0.88 | AN37: 1.1 | AO37: 1.66 | AP37: 1.36 | AQ37: 1.88 | AR37: 2.02 | AS37: 2.91 | AT37: 2.1 | AU37: 1.16 | AV37: 0.88 | AW37: 0.795 | AX37: N/A | AY37: N/A | AZ37: 2.5 | BA37: 116.15 | BB37: 121.15 | BC37: 0.00374 | BD37: 0.248 | BE37: 1.638 | BF37: 9.029 | BG37: 0 | BH37: 0.00949 | BI37: N/A | BJ37: 0.116 | BK37: N/A | BL37: N/A | BM37: N/A | BN37: N/A | BO37: N/A | BP37: N/A | BQ37: N/A | BR37: 25 | BS37: 0.013 | BT37: 32 | BU37: 6 | BV37: 0.1875 | BW37: 1 | BX37: 1.0209181e-10 | BY37: 1.4675015e-09 | BZ37: N/A | CA37: N/A | CB37: 33
A38: Rb | B38: [Kr]5s1 | C38: 85.4678 | D38: 37 | E38: 5 | F38: 1 | G38: 0 | H38: 1 | I38: 4 | J38: 1 | K38: 1 | L38: 0 | M38: 0 | N38: 0 | O38: 1 | P38: 6 | Q38: 10 | R38: 14 | S38: 1 | T38: 1 | U38: 1 | V38: 1 | W38: 1 | X38: 2.769 | Y38: 1.519 | Z38: 4.1771 | AA38: 0.48715558 | AB38: 2.34 | AC38: 2.0135 | AD38: 0.82 | AE38: 0.8 | AF38: 2.34 | AG38: 0.82 | AH38: 0.706 | AI38: 0.83 | AJ38: 1.05 | AK38: 0.78 | AL38: 0.342 | AM38: 2.65 | AN38: 2.11 | AO38: 1.66 | AP38: 1.52 | AQ38: 2.44 | AR38: 2.9 | AS38: 4.1 | AT38: 1.66 | AU38: 2.2 | AV38: 2.35 | AW38: 2.287 | AX38: 2.48 | AY38: 2.16 | AZ38: 47.3 | BA38: 312.05 | BB38: 959.15 | BC38: 1.53 | BD38: 0.363 | BE38: 2.192 | BF38: 72.216 | BG38: 86 | BH38: 58.2 | BI38: 9e-06 | BJ38: 0.852 | BK38: 3.1 | BL38: N/A | BM38: 2.4 | BN38: N/A | BO38: 0.000216 | BP38: 1.2e-07 | BQ38: 8300000 | BR38: 0.38 | BS38: 0.0003 | BT38: 32 | BU38: 1 | BV38: 0.03125 | BW38: 1 | BX38: 9.1882627e-05 | BY38: 2.3121302e-10 | BZ38: 6000 | CA38: 6000 | CB38: 1200
A39: Sr | B39: [Kr]5s2 | C39: 87.62 | D39: 38 | E39: 5 | F39: 2 | G39: 0 | H39: 1 | I39: 8 | J39: 2 | K39: 2 | L39: 0 | M39: 0 | N39: 0 | O39: 0 | P39: 6 | Q39: 10 | R39: 14 | S39: 2 | T39: 2 | U39: 2 | V39: 2 | W39: 2 | X39: 3.234 | Y39: 1.301 | Z39: 5.6949 | AA39: 0.05186612 | AB39: 2 | AC39: 2.5849 | AD39: 0.95 | AE39: 1.13 | AF39: 2 | AG39: 0.95 | AH39: 0.963 | AI39: 1.06 | AJ39: 1.63 | AK39: 1 | AL39: 0.744 | AM39: 2.19 | AN39: 1.92 | AO39: 1.32 | AP39: 1.18 | AQ39: 2.12 | AR39: 2.55 | AS39: 3.21 | AT39: 1.32 | AU39: 1.95 | AV39: 2 | AW39: 1.836 | AX39: 2.148 | AY39: 1.914 | AZ39: 27.6 | BA39: 1042.15 | BB39: 1657.15 | BC39: 2.63 | BD39: 0.3 | BE39: 8.3 | BF39: 144 | BG39: 164 | BH39: 35.3 | BI39: 2.25e-05 | BJ39: 1.72 | BK39: 12 | BL39: 6.1 | BM39: N/A | BN39: N/A | BO39: N/A | BP39: 1.3e-07 | BQ39: 7700000 | BR39: 1.2 | BS39: 0.0005 | BT39: 33 | BU39: 4 | BV39: 0.12121212 | BW39: 1 | BX39: 0.00037773969 | BY39: 7.6636191e-10 | BZ39: 4179 | CA39: 3000 | CB39: 100
A40: Y | B40: [Kr]5s24d1 | C40: 88.90584 | D40: 39 | E40: 5 | F40: 3 | G40: 2 | H40: 1 | I40: 12 | J40: 3 | K40: 2 | L40: 0 | M40: 1 | N40: 0 | O40: 0 | P40: 6 | Q40: 9 | R40: 14 | S40: 3 | T40: 2 | U40: 1 | V40: 3 | W40: 3 | X40: 3.379 | Y40: 1.245 | Z40: 6.2173 | AA40: 0.310865 | AB40: 3.19 | AC40: 2.7237 | AD40: 1.22 | AE40: 1.41 | AF40: 3.19 | AG40: 1.22 | AH40: 1.12 | AI40: 1.11 | AJ40: 1.76 | AK40: 1.3 | AL40: 0.868 | AM40: 2.12 | AN40: 1.62 | AO40: 1.04 | AP40: 0.9 | AQ40: 1.79 | AR40: 2.4 | AS40: 2.94 | AT40: 1.04 | AU40: 1.9 | AV40: 1.85 | AW40: 1.693 | AX40: 1.797 | AY40: 1.616 | AZ40: 22.7 | BA40: 1796.15 | BB40: 3610.15 | BC40: 4.47 | BD40: 0.3 | BE40: 11.4 | BF40: 363 | BG40: 423 | BH40: 17.2 | BI40: 1.06e-05 | BJ40: 4.37 | BK40: 41.2 | BL40: 26 | BM40: 64 | BN40: N/A | BO40: 0.588 | BP40: 5.7e-07 | BQ40: 1800000 | BR40: 1.28 | BS40: 0.00059 | BT40: 33 | BU40: 1 | BV40: 0.03030303 | BW40: 1 | BX40: 3.3690297e-05 | BY40: 1.5131571e-10 | BZ40: 9834 | CA40: 2646 | CB40: 220
...

Sheet Features
A1: Composition | B1: Feature 1 Atomic weight average | C1: Feature 2 Atomic weight Sum | D1: Feature 3 Atomic weight variance | E1: Feature 4 Atomic weight max | F1: Feature 5 Atomic weight mim | G1: Feature 6 Atomic weight diference | H1: Feature 7 Atomic number average | I1: Feature 8 Atomic number sum | J1: Feature 9 Atomic number variance | K1: Feature 10 Atomic number max | L1: Feature 11 Atomic number mim | M1: Feature 12 Atomic number diference | N1: Feature 13 Period avarage | O1: Feature 14 Period sum | P1: Feature 15 Period variance | Q1: Feature 16 Period max | R1: Feature 17 Period mim | S1: Feature 18 Period diference | T1: Feature 19 Group avarage | U1: Feature 20 Group sum | V1: Feature 21 Group variance | W1: Feature 22 Group max | X1: Feature 23 Group mim | Y1: Feature 24 Group diference | Z1: Feature 25 Mendeleev number avarage | AA1: Feature 26 Mendeleev number sum | AB1: Feature 27 Mendeleev number variance | AC1: Feature 28 Mendeleev number max | AD1: Feature 29 Mendeleev number mim | AE1: Feature 30 Mendeleev number diference | AF1: Feature 31 Families avarage | AG1: Feature 32 Families sum | AH1: Feature 33 Families variance | AI1: Feature 34 Families max | AJ1: Feature 35 Families mim | AK1: Feature 36 Families diference | AL1: Feature 37 valence s avarage | AM1: Feature 38 valence s sum | AN1: Feature 39 valence s variance | AO1: Feature 40 valence s max | AP1: Feature 41 valence s mim | AQ1: Feature 42 valence s diference | AR1: Feature 43 valence p avarage | AS1: Feature 44 valence p sum | AT1: Feature 45 valence s variance | AU1: Feature 46 valence p max | AV1: Feature 47 valence p mim | AW1: Feature 48 valence p diference | AX1: Feature 49 valence d avarage | AY1: Feature 50 valence d sum | AZ1: Feature 51 valence d variance | BA1: Feature 52 valence d max | BB1: Feature 53 valence d mim | BC1: Feature 54 valence d diference | BD1: Feature 55 valence f avarage | BE1: Feature 56 valence f sum | BF1: Feature 57 valence f variance | BG1: Feature 58 valence f max | BH1: Feature 59 valence f mim | BI1: Feature 60 valence f diference | BJ1: Feature 61 no. of valence electrons avarage | BK1: Feature 62 no. of valence electrons sum | BL1: Feature 63 no. of valence electrons variance | BM1: Feature 64 no. of valence electrons max | BN1: Feature 65 no. of valence electrons mim | BO1: Feature 66 no. of valence electrons diference | BP1: Feature 67 outer shell electrons avarage | BQ1: Feature 68 outer shell electrons sum | BR1: Feature 69 outer shell electrons variance | BS1: Feature 70 outer shell electrons max | BT1: Feature 71 outer shell electrons mim | BU1: Feature 72 no. of valence electrons diference | BV1: Feature 73 Gilman no. of valence electrons avarage | BW1: Feature 74 Gilman no. of valence electrons sum | BX1: Feature 75 Gilman no. of valence electrons variance | BY1: Feature 76 Gilman no. of valence electrons max | BZ1: Feature 77 Gilman no. of valence electrons mim | CA1: Feature 78 Gilman no. of valence electrons diference | CB1: Feature 79 Metallic valence avarage | CC1: Feature 80 Metallic valence sum | CD1: Feature 81 Metallic valencevariance | CE1: Feature 82 Metallic valence max | CF1: Feature 83 Metallic valence mim | CG1: Feature 84 Metallic valence diference | CH1: Feature 85 Ionization energy (eV) avarage | CI1: Feature 86 Ionization energy (eV) sum | CJ1: Feature 87 Ionization energy (eV) variance | CK1: Feature 88 Ionization energy (eV) max | CL1: Feature 89 Ionization energy (eV) mim | CM1: Feature 90 Ionization energy (eV) diference | CN1: Feature 91 Pauling EM avarage | CO1: Feature 92 Pauling EN sum | CP1: Feature 93 Pauling EN variance | CQ1: Feature 94 Pauling EM max | CR1: Feature 95 Pauling EM mim | CS1: Feature 96 Pauling EN diference | CT1: Feature 97 Martynov Batsanov EN avarage | CU1: Feature 98 Martynov Batsanov EN sum | CV1: Feature 99 Martynov Batsanov EN variance | CW1: Feature 100 Martynov Batsanov EN max | CX1: Feature 101 Martynov Batsanov EN mim | CY1: Feature 102 Martynov Batsanov EN diference | CZ1: Feature 103 Mulliken EM avarage | DA1: Feature 104 Mulliken EN sum | DB1: Feature 105 Mulliken EM variance | DC1: Feature 106 Mulliken EM max | DD1: Feature 107 Mulliken EM mim | DE1: Feature 108 Mulliken EM diference | DF1: Feature 109 Allred Rockow EN avarage | DG1: Feature 110 Allred Rockow EN sum | DH1: Feature 111 Allred Rockow EN variance | DI1: Feature 112 Allred Rockow EN max | DJ1: Feature 113 Allred Rockow EN mim | DK1: Feature 114 Allred Rockow EN diference | DL1: Feature 121 Atomic radius calculated avarage | DM1: Feature 122 Atomic radius calculated sum | DN1: Feature 123 Atomic radius calculated variance | DO1: Feature 124 Atomic radius calculated max | DP1: Feature 125 Atomic radius calculated mim | DQ1: Feature 126 Atomic radius calculated diference | DR1: Feature 127 Covalent radius avarage | DS1: Feature 128 Covalent radius sum | DT1: Feature 129 Covalent radius variance | DU1: Feature 130 Covalent radius max | DV1: Feature 131 Covalent radius mim | DW1: Feature 132 Covalent radius diference | DX1: Feature 133 Ionic radius avarage | DY1: Feature 134 Ionic radius sum | DZ1: Feature 135 Ionic radius variance | EA1: Feature 136 Ionic radius max | EB1: Feature 137 Ionic radius mim | EC1: Feature 138 Ionic radius diference | ED1: Feature 139 Zunger radii sum avarage | EE1: Feature 140 Zunger radii sum sum | EF1: Feature 141 Zunger radii sum variance | EG1: Feature 142 Zunger radii sum max | EH1: Feature 143 Zunger radii sum mim | EI1: Feature 144 Zunger radii sum diference | EJ1: Feature 145 Crystal radius avarage | EK1: Feature 146 Crystal radius sum | EL1: Feature 147 Crystal radius variance | EM1: Feature 148 Crystal radius max | EN1: Feature 149 Crystal radius mim | EO1: Feature 150 Crystal radius diference | EP1: Feature 151 polarizability, A^3 avarage | EQ1: Feature 152 polarizability, A^3 sum | ER1: Feature 153 polarizability, A^3 variance | ES1: Feature 154 polarizability, A^3 max | ET1: Feature 155 polarizability, A^3 mim | EU1: Feature 156 polarizability, A^3 diference | EV1: Feature 157 Melting point, K avarage | EW1: Feature 158 Melting point, K sum | EX1: Feature 159 Melting point, K variance | EY1: Feature 160 Melting point, K max | EZ1: Feature 161 pMelting point, K mim | FA1: Feature 162 Melting point, K diference | FB1: Feature 163 Boiling point, K avarage | FC1: Feature 164 Boiling point, K sum | FD1: Feature 165 Boiling point, K variance | FE1: Feature 166 Boiling point, K max | FF1: Feature 167 Boiling point, K mim | FG1: Feature 168 Boiling point, K diference | FH1: Feature 169 Density, g/mL avarage | FI1: Feature 170 Density, g/mL sum | FJ1: Feature 171 Density, g/mL variance | FK1: Feature 172 Density, g/mL max | FL1: Feature 173 Density, g/mL mim | FM1: Feature 174 Density, g/mL diference | FN1: Feature 175 Specific heat, J/g K avarage | FO1: Feature 176 Specific heat, J/g K sum | FP1: Feature 177 Specific heat, J/g K variance | FQ1: Feature 178 Specific heat, J/g K max | FR1: Feature 179 Specific heat, J/g K mim | FS1: Feature 180 Specific heat, J/g K diference | FT1: Feature 181 Heat of fusion, kJ/mol avarage | FU1: Feature 182 Heat of fusion, kJ/mol sum | FV1: Feature 183 Heat of fusion, kJ/mol variance | FW1: Feature 184 Heat of fusion, kJ/mol max | FX1: Feature 185 Heat of fusion, kJ/mol mim | FY1: Feature 186 Heat of fusion, kJ/mol diference | FZ1: Feature 187 Thermal conductivity, W/m K avarage | GA1: Feature 188 Thermal conductivity, W/m K sum | GB1: Feature 189 Thermal conductivity, W/m K variance | GC1: Feature 190 Thermal conductivity, W/m K max | GD1: Feature 191 Thermal conductivity, W/m K mim | GE1: Feature 192 Thermal conductivity, W/m K diference | GF1: Feature 193 Cohesive energy avarage | GG1: Feature 194 Cohesive energy sum | GH1: Feature 195 Cohesive energy variance | GI1: Feature 196 Cohesive energy max | GJ1: Feature 197 Cohesive energy mim | GK1: Feature 198 Cohesive energy diference | GL1: Feature 199 Space group number | GM1: Feature 200 Crystal system | GN1: Feature 216 Concentration 2
